Workbook

Sheet DURATIONS_202605221527
A1: session_id | B1: player | C1: started | D1: minutes | E1: duration | F1: player
A2: 8729 | B2: vdubey26@gmail.com | C2: 46148.475 | D2: 32 | E2: 32m 37s | F2: =A2 -> 8729
A3: 8750 | B3: kritika.iyer30@gmail.com | C3: 46149.364 | D3: 43 | E3: 43m 10s | F3: =A3 -> 8750
A4: 8817 | B4: vdubey26@gmail.com | C4: 46153.472 | D4: 26 | E4: 26m 01s | F4: =A4 -> 8817
A5: 8851 | B5: angad.sharma@zomato.com | C5: 46154.469 | D5: 35 | E5: 35m 24s | F5: =A5 -> 8851
A6: 8860 | B6: michael.ward@6dg.co.uk | C6: 46154.589 | D6: 30 | E6: 30m 05s | F6: =A6 -> 8860
A7: 8902 | B7: sam.williams@gearset.com | C7: 46156.38 | D7: 38 | E7: 38m 06s | F7: =A7 -> 8902
A8: 8930 | B8: julian.wreford@gearset.com | C8: 46157.338 | D8: 26 | E8: 26m 29s | F8: =A8 -> 8930
A9: 8974 | B9: chris.davis@storiogroup.com | C9: 46160.424 | D9: 25 | E9: 25m 56s | F9: =A9 -> 8974
A10: 8986 | B10: oli@gearset.com | C10: 46160.549 | D10: 23 | E10: 23m 04s | F10: =A10 -> 8986
A11: 8993 | B11: sangeetha.niranjan@thetrainline.com | C11: 46160.587 | D11: 33 | E11: 33m 27s | F11: =A11 -> 8993
A12: 8997 | B12: fraser.gillies@thetrainline.com | C12: 46160.634 | D12: 32 | E12: 32m 24s | F12: =A12 -> 8997
A13: 9021 | B13: milisavljevic@rushstreetinteractive.com | C13: 46161.381 | D13: 44 | E13: 44m 11s | F13: =A13 -> 9021
... A51: 9177 | B51: aoife.breen@options-it.com | C51: 46170.421 | D51: 30 | E51: 30m 42s | F51: =A51 -> 9177

Sheet Composite Scores
A1: Session ID | B1: Facet Score | C1: Marker Score | D1: Composite Score | E1: Processed At | F1: player | G1: dominos?
A2: 9532 | B2: 2.80 / 4 | C2: 3.83 / 4 | D2: 70.3 | E2: 2026-06-19 12:13 UTC | F2: =VLOOKUP(A2, 'Snipe Hunt Time'!C$2:F$200, 4, FALSE) -> lew.radam@withersworldwide.com
A3: 8851 | B3: 3.00 / 4 | C3: 3.33 / 4 | D3: 70 | E3: 2026-05-20 22:17 UTC | F3: =VLOOKUP(A3, 'Snipe Hunt Time'!C$2:F$200, 4, FALSE) -> angad.sharma@zomato.com | G3: =IF(ISNUMBER(FIND("dominos", F3)), "dominos", "-") -> -
A4: 9497 | B4: 3.00 / 4 | C4: 2.83 / 4 | D4: 65 | E4: 2026-06-19 11:58 UTC | F4: =VLOOKUP(A4, 'Snipe Hunt Time'!C$2:F$200, 4, FALSE) -> rosie.miller@gearset.com
A5: 9084 | B5: 3.00 / 4 | C5: 2.75 / 4 | D5: 64.2 | E5: 2026-05-22 09:58 UTC | F5: =VLOOKUP(A5, 'Snipe Hunt Time'!C$2:F$200, 4, FALSE) -> david.emmerson@gearset.com | G5: =IF(ISNUMBER(FIND("dominos", F5)), "dominos", "-") -> -
A6: 9456 | B6: 3.00 / 4 | C6: 2.75 / 4 | D6: 64.2 | E6: 2026-06-15 09:00 UTC | F6: =VLOOKUP(A6, 'Snipe Hunt Time'!C$2:F$200, 4, FALSE) -> qasim.altaf@6dg.co.uk
A7: 9063 | B7: 3.00 / 4 | C7: 2.67 / 4 | D7: 63.4 | E7: 2026-05-22 09:28 UTC | F7: =VLOOKUP(A7, 'Snipe Hunt Time'!C$2:F$200, 4, FALSE) -> andy.knox@gearset.com | G7: =IF(ISNUMBER(FIND("dominos", F7)), "dominos", "-") -> -
A8: 9291 | B8: 3.00 / 4 | C8: 2.58 / 4 | D8: 62.5 | E8: 2026-06-04 09:04 UTC | F8: =VLOOKUP(A8, 'Snipe Hunt Time'!C$2:F$200, 4, FALSE) -> remi.deverclos@albelli.com | G8: =IF(ISNUMBER(FIND("dominos", F8)), "dominos", "-") -> -
A9: 9503 | B9: 2.80 / 4 | C9: 3.00 / 4 | D9: 62 | E9: 2026-06-19 12:02 UTC | F9: =VLOOKUP(A9, 'Snipe Hunt Time'!C$2:F$200, 4, FALSE) -> kenny.vaughan@gearset.com
A10: 9142 | B10: 2.80 / 4 | C10: 2.83 / 4 | D10: 60.3 | E10: 2026-05-26 15:59 UTC | F10: =VLOOKUP(A10, 'Snipe Hunt Time'!C$2:F$200, 4, FALSE) -> joe.muller@sonic.com | G10: =IF(ISNUMBER(FIND("dominos", F10)), "dominos", "-") -> -
A11: 9183 | B11: 2.80 / 4 | C11: 2.75 / 4 | D11: 59.5 | E11: 2026-05-28 13:49 UTC | F11: =VLOOKUP(A11, 'Snipe Hunt Time'!C$2:F$200, 4, FALSE) -> gabriel@gearset.com | G11: =IF(ISNUMBER(FIND("dominos", F11)), "dominos", "-") -> -
A12: 9185 | B12: 2.80 / 4 | C12: 2.75 / 4 | D12: 59.5 | E12: 2026-05-28 13:51 UTC | F12: =VLOOKUP(A12, 'Snipe Hunt Time'!C$2:F$200, 4, FALSE) -> amy.jeanes@exclaimer.com | G12: =IF(ISNUMBER(FIND("dominos", F12)), "dominos", "-") -> -
A13: 9349 | B13: 2.80 / 4 | C13: 2.75 / 4 | D13: 59.5 | E13: 2026-06-05 09:50 UTC | F13: =VLOOKUP(A13, 'Snipe Hunt Time'!C$2:F$200, 4, FALSE) -> dennis.verheijden@albelli.com | G13: =IF(ISNUMBER(FIND("dominos", F13)), "dominos", "-") -> -
A14: 9465 | B14: 2.80 / 4 | C14: 2.75 / 4 | D14: 59.5 | E14: 2026-06-15 09:12 UTC | F14: =VLOOKUP(A14, 'Snipe Hunt Time'!C$2:F$200, 4, FALSE) -> sebastian.eberlein@emnify.com
A15: 8771 | B15: 2.60 / 4 | C15: 3.08 / 4 | D15: 58.1 | E15: 2026-05-20 22:12 UTC | F15: =VLOOKUP(A15, 'Snipe Hunt Time'!C$2:F$200, 4, FALSE) -> baljit.chima@6dg.co.uk | G15: =IF(ISNUMBER(FIND("dominos", F15)), "dominos", "-") -> -
A16: 8974 | B16: 2.80 / 4 | C16: 2.58 / 4 | D16: 57.8 | E16: 2026-05-22 08:42 UTC | F16: =VLOOKUP(A16, 'Snipe Hunt Time'!C$2:F$200, 4, FALSE) -> chris.davis@storiogroup.com | G16: =IF(ISNUMBER(FIND("dominos", F16)), "dominos", "-") -> -
A17: 9030 | B17: 2.60 / 4 | C17: 3.00 / 4 | D17: 57.3 | E17: 2026-05-22 08:56 UTC | F17: =VLOOKUP(A17, 'Snipe Hunt Time'!C$2:F$200, 4, FALSE) -> daniel.cook@thetrainline.com | G17: =IF(ISNUMBER(FIND("dominos", F17)), "dominos", "-") -> -
A18: 9267 | B18: 2.60 / 4 | C18: 2.75 / 4 | D18: 54.8 | E18: 0 | F18: =VLOOKUP(A18, 'Snipe Hunt Time'!C$2:F$200, 4, FALSE) -> andrew.mccready@storiogroup.com | G18: =IF(ISNUMBER(FIND("dominos", F18)), "dominos", "-") -> -
A19: 8860 | B19: 2.60 / 4 | C19: 2.75 / 4 | D19: 54.8 | E19: 2026-06-12 15:14 UTC | F19: =VLOOKUP(A19, 'Snipe Hunt Time'!C$2:F$200, 4, FALSE) -> michael.ward@6dg.co.uk
A20: 9082 | B20: 2.60 / 4 | C20: 2.67 / 4 | D20: 54 | E20: 2026-05-22 09:54 UTC | F20: =VLOOKUP(A20, 'Snipe Hunt Time'!C$2:F$200, 4, FALSE) -> jernej.primcic@thomsonreuters.com | G20: =IF(ISNUMBER(FIND("dominos", F20)), "dominos", "-") -> -
A21: 8902 | B21: 2.60 / 4 | C21: 2.67 / 4 | D21: 54 | E21: 2026-05-21 15:29 UTC | F21: =VLOOKUP(A21, 'Snipe Hunt Time'!C$2:F$200, 4, FALSE) -> sam.williams@gearset.com | G21: =IF(ISNUMBER(FIND("dominos", F21)), "dominos", "-") -> -
A22: 9229 | B22: 2.60 / 4 | C22: 2.67 / 4 | D22: 54 | E22: 2026-06-01 15:20 UTC | F22: =VLOOKUP(A22, 'Snipe Hunt Time'!C$2:F$200, 4, FALSE) -> neha.gupta@zomato.com | G22: =IF(ISNUMBER(FIND("dominos", F22)), "dominos", "-") -> -
A23: 9080 | B23: 2.60 / 4 | C23: 2.58 / 4 | D23: 53.1 | E23: 2026-05-22 09:52 UTC | F23: =VLOOKUP(A23, 'Snipe Hunt Time'!C$2:F$200, 4, FALSE) -> alexander.hof@storiogroup.com | G23: =IF(ISNUMBER(FIND("dominos", F23)), "dominos", "-") -> -
A24: 9051 | B24: 2.60 / 4 | C24: 2.58 / 4 | D24: 53.1 | E24: 2026-05-22 09:10 UTC | F24: =VLOOKUP(A24, 'Snipe Hunt Time'!C$2:F$200, 4, FALSE) -> jack.norris@exclaimer.com | G24: =IF(ISNUMBER(FIND("dominos", F24)), "dominos", "-") -> -
A25: 9109 | B25: 2.60 / 4 | C25: 2.58 / 4 | D25: 53.1 | E25: 2026-05-22 15:04 UTC | F25: =VLOOKUP(A25, 'Snipe Hunt Time'!C$2:F$200, 4, FALSE) -> patrick.boyd@gearset.com | G25: =IF(ISNUMBER(FIND("dominos", F25)), "dominos", "-") -> -
A26: 9330 | B26: 2.60 / 4 | C26: 2.58 / 4 | D26: 53.1 | E26: 2026-06-04 09:22 UTC | F26: =VLOOKUP(A26, 'Snipe Hunt Time'!C$2:F$200, 4, FALSE) -> leigh.burton@sonic.com | G26: =IF(ISNUMBER(FIND("dominos", F26)), "dominos", "-") -> -
A27: 9355 | B27: 2.60 / 4 | C27: 2.58 / 4 | D27: 53.1 | E27: 2026-06-05 09:54 UTC | F27: =VLOOKUP(A27, 'Snipe Hunt Time'!C$2:F$200, 4, FALSE) -> nathaniel.vanderpuye@exclaimer.com | G27: =IF(ISNUMBER(FIND("dominos", F27)), "dominos", "-") -> -
A28: 9371 | B28: 2.60 / 4 | C28: 2.58 / 4 | D28: 53.1 | E28: 2026-06-05 15:42 UTC | F28: =VLOOKUP(A28, 'Snipe Hunt Time'!C$2:F$200, 4, FALSE) -> antoine.poullet@gearset.com | G28: =IF(ISNUMBER(FIND("dominos", F28)), "dominos", "-") -> -
A29: 8930 | B29: 2.60 / 4 | C29: 2.50 / 4 | D29: 52.3 | E29: 2026-05-21 15:35 UTC | F29: =VLOOKUP(A29, 'Snipe Hunt Time'!C$2:F$200, 4, FALSE) -> julian.wreford@gearset.com | G29: =IF(ISNUMBER(FIND("dominos", F29)), "dominos", "-") -> -
A30: 9191 | B30: 2.60 / 4 | C30: 2.50 / 4 | D30: 52.3 | E30: 2026-05-29 15:05 UTC | F30: =VLOOKUP(A30, 'Snipe Hunt Time'!C$2:F$200, 4, FALSE) -> conor.reed@eso.com | G30: =IF(ISNUMBER(FIND("dominos", F30)), "dominos", "-") -> -
A31: 9270 | B31: 2.60 / 4 | C31: 2.50 / 4 | D31: 52.3 | E31: 2026-06-02 15:59 UTC | F31: =VLOOKUP(A31, 'Snipe Hunt Time'!C$2:F$200, 4, FALSE) -> ohi.james@exclaimer.com | G31: =IF(ISNUMBER(FIND("dominos", F31)), "dominos", "-") -> -
A32: 9273 | B32: 2.60 / 4 | C32: 2.50 / 4 | D32: 52.3 | E32: 2026-06-02 16:01 UTC | F32: =VLOOKUP(A32, 'Snipe Hunt Time'!C$2:F$200, 4, FALSE) -> constant.zomer@albelli.com | G32: =IF(ISNUMBER(FIND("dominos", F32)), "dominos", "-") -> -
A33: 9401 | B33: 2.60 / 4 | C33: 2.50 / 4 | D33: 52.3 | E33: 2026-06-11 11:33 UTC | F33: =VLOOKUP(A33, 'Snipe Hunt Time'!C$2:F$200, 4, FALSE) -> ciaran.hurley@options-it.com
A34: 9423 | B34: 2.60 / 4 | C34: 2.50 / 4 | D34: 52.3 | E34: 2026-06-11 11:39 UTC | F34: =VLOOKUP(A34, 'Snipe Hunt Time'!C$2:F$200, 4, FALSE) -> barry@gearset.com
A35: 9462 | B35: 2.60 / 4 | C35: 2.50 / 4 | D35: 52.3 | E35: 2026-06-15 09:08 UTC | F35: =VLOOKUP(A35, 'Snipe Hunt Time'!C$2:F$200, 4, FALSE) -> eamonn.boyle@gearset.com
A36: 9054 | B36: 2.60 / 4 | C36: 2.42 / 4 | D36: 51.5 | E36: 2026-05-22 09:16 UTC | F36: =VLOOKUP(A36, 'Snipe Hunt Time'!C$2:F$200, 4, FALSE) -> jessica.light@exclaimer.com | G36: =IF(ISNUMBER(FIND("dominos", F36)), "dominos", "-") -> -
A37: 8986 | B37: 2.60 / 4 | C37: 2.42 / 4 | D37: 51.5 | E37: 2026-05-22 08:44 UTC | F37: =VLOOKUP(A37, 'Snipe Hunt Time'!C$2:F$200, 4, FALSE) -> oli@gearset.com | G37: =IF(ISNUMBER(FIND("dominos", F37)), "dominos", "-") -> -
A38: 9108 | B38: 2.60 / 4 | C38: 2.42 / 4 | D38: 51.5 | E38: 2026-05-22 14:08 UTC | F38: =VLOOKUP(A38, 'Snipe Hunt Time'!C$2:F$200, 4, FALSE) -> calum.mcdowell@storiogroup.com | G38: =IF(ISNUMBER(FIND("dominos", F38)), "dominos", "-") -> -
A39: 9190 | B39: 2.60 / 4 | C39: 2.42 / 4 | D39: 51.5 | E39: 2026-05-29 15:03 UTC | F39: =VLOOKUP(A39, 'Snipe Hunt Time'!C$2:F$200, 4, FALSE) -> leah.murphy@options-it.com | G39: =IF(ISNUMBER(FIND("dominos", F39)), "dominos", "-") -> -
A40: 9280 | B40: 2.60 / 4 | C40: 2.42 / 4 | D40: 51.5 | E40: 2026-06-04 09:02 UTC | F40: =VLOOKUP(A40, 'Snipe Hunt Time'!C$2:F$200, 4, FALSE) -> lana.m@slice.com | G40: =IF(ISNUMBER(FIND("dominos", F40)), "dominos", "-") -> -
...

Sheet Snipe Hunt Time
A1: player | B1: started | C1: session_id | D1: minutes | E1: duration | F1: player cc | G1: attempts | H1: attempt_number
A2: suraj.singhdadwal@ig.com | B2: 46178.557 | C2: 9368 | F2: suraj.singhdadwal@ig.com | G2: 1 | H2: 1
A3: prashanta.agarwala@zomato.com | B3: 46168.38 | C3: 9120 | F3: prashanta.agarwala@zomato.com | G3: 1 | H3: 1
A4: praveen.sadul@dominos.co.uk | B4: 46184.306 | C4: 9418 | F4: praveen.sadul@dominos.co.uk | G4: 1 | H4: 1
A5: qasim.altaf@6dg.co.uk | B5: 46185.587 | C5: 9451 | F5: qasim.altaf@6dg.co.uk | G5: 2 | H5: 1
A6: r.enchill-balogun@6dg.co.uk | B6: 46182.507 | C6: 9395 | F6: r.enchill-balogun@6dg.co.uk | G6: 1 | H6: 1
A7: ravikiran.s@zomato.com | B7: 46174.466 | C7: 9227 | F7: ravikiran.s@zomato.com | G7: 1 | H7: 1
A8: remi.deverclos@albelli.com | B8: 46176.38 | C8: 9291 | F8: remi.deverclos@albelli.com | G8: 1 | H8: 1
A9: ryan.allen@6dg.co.uk | B9: 46182.38 | C9: 9392 | F9: ryan.allen@6dg.co.uk | G9: 1 | H9: 1
A10: saikrishnajami60@gmail.com | B10: 46182.319 | C10: 9389 | F10: saikrishnajami60@gmail.com | G10: 1 | H10: 1
A11: samantha.wright@exclaimer.com | B11: 46176.463 | C11: 9304 | F11: samantha.wright@exclaimer.com | G11: 1 | H11: 1
A12: shea_mcsorley@firstderivative.com | B12: 46176.466 | C12: 9305 | F12: shea_mcsorley@firstderivative.com | G12: 1 | H12: 1
A13: aamir.kapasi@albelli.com | B13: 46162.379 | C13: 9048 | F13: aamir.kapasi@albelli.com | G13: 1 | H13: 1
... A42: jessica.light@exclaimer.com | B42: 46162.505 | C42: 9054 | F42: jessica.light@exclaimer.com | G42: 1 | H42: 1
A43: akshat.goel@zomato.com | B43: 46180.613 | C43: 9377 | D43: 15 | E43: 15m 22s | F43: akshat.goel@zomato.com | G43: 3 | H43: 3
A44: sebastian.eberlein@emnify.com | B44: 46186.66 | C44: 9465 | D44: 17 | E44: 17m 34s | F44: sebastian.eberlein@emnify.com | G44: 2 | H44: 2
A45: soumya.jk@thetrainline.com | B45: 46162.548 | C45: 9057 | D45: 20 | E45: 20m 14s | F45: soumya.jk@thetrainline.com | G45: 1 | H45: 1
A46: amy.jeanes@exclaimer.com | B46: 46170.545 | C46: 9185 | D46: 20 | E46: 20m 29s | F46: amy.jeanes@exclaimer.com | G46: 1 | H46: 1
A47: swetha.nayudu@dominos.co.uk | B47: 46176.567 | C47: 9317 | D47: 20 | E47: 20m 40s | F47: swetha.nayudu@dominos.co.uk | G47: 3 | H47: 3
A48: manuj.grover@zomato.com | B48: 46178.403 | C48: 9361 | D48: 21 | E48: 21m 21s | F48: manuj.grover@zomato.com | G48: 1 | H48: 1
A49: sebastian.eberlein@emnify.com | B49: 46184.592 | C49: 9430 | D49: 21 | E49: 21m 34s | F49: sebastian.eberlein@emnify.com | G49: 2 | H49: 1
A50: akshat.goel@zomato.com | B50: 46180.594 | C50: 9376 | D50: 22 | E50: 22m 34s | F50: akshat.goel@zomato.com | G50: 3 | H50: 2
A51: amelia.horwood@options-it.com | B51: 46170.385 | C51: 9173 | D51: 22 | E51: 22m 48s | F51: amelia.horwood@options-it.com | G51: 1 | H51: 1
A52: sakib.malik@zomato.com | B52: 46162.282 | C52: 9044 | D52: 22 | E52: 22m 58s | F52: sakib.malik@zomato.com | G52: 1 | H52: 1
A53: oli@gearset.com | B53: 46160.549 | C53: 8986 | D53: 23 | E53: 23m 04s | F53: oli@gearset.com | G53: 1 | H53: 1
A54: raunak.shamnani@zomato.com | B54: 46164.545 | C54: 9107 | D54: 23 | E54: 23m 16s | F54: raunak.shamnani@zomato.com | G54: 1 | H54: 1
... A155: arek.jadwiszczak@thomsonreuters.com | B155: 46169.549 | C155: 9162 | D155: 45 | E155: 45m 12s | F155: arek.jadwiszczak@thomsonreuters.com | G155: 1 | H155: 1

Sheet Snipe Hunt Time copy (jun5)
A1: player | B1: started | C1: session_id | D1: minutes | E1: duration | F1: player cc
A2: baljit.chima@6dg.co.uk | B2: 46149.63 | C2: 8771 | F2: =A2 -> baljit.chima@6dg.co.uk
A3: jamie.buchanan@thetrainline.com | B3: 46150.634 | C3: 8791 | F3: =A3 -> jamie.buchanan@thetrainline.com
A4: william.vanduynhoven@thomsonreuters.com | B4: 46156.635 | C4: 8923 | F4: =A4 -> william.vanduynhoven@thomsonreuters.com
A5: naeem.khan@6dg.co.uk | B5: 46160.641 | C5: 8998 | F5: =A5 -> naeem.khan@6dg.co.uk
A6: aamir.kapasi@albelli.com | B6: 46162.379 | C6: 9048 | F6: =A6 -> aamir.kapasi@albelli.com
A7: jessica.light@exclaimer.com | B7: 46162.505 | C7: 9054 | F7: =A7 -> jessica.light@exclaimer.com
A8: swetha.nayudu@dominos.co.uk | B8: 46162.549 | C8: 9058 | F8: =A8 -> swetha.nayudu@dominos.co.uk
A9: tim.redding@photobox.com | B9: 46162.549 | C9: 9059 | F9: =A9 -> tim.redding@photobox.com
A10: leigh.burton@sonic.com | B10: 46162.63 | C10: 9062 | F10: =A10 -> leigh.burton@sonic.com
A11: andy.knox@gearset.com | B11: 46162.633 | C11: 9063 | F11: =A11 -> andy.knox@gearset.com
A12: venkatmohan.kumar@ig.com | B12: 46163.425 | C12: 9077 | F12: =A12 -> venkatmohan.kumar@ig.com
A13: zishan.sohail@6dg.co.uk | B13: 46163.587 | C13: 9087 | F13: =A13 -> zishan.sohail@6dg.co.uk
A14: soumya.jk@thetrainline.com | B14: 46162.548 | C14: 9057 | D14: 20 | E14: 20m 14s | F14: =A14 -> soumya.jk@thetrainline.com
A15: amelia.horwood@options-it.com | B15: 46170.385 | C15: 9173 | D15: 22 | E15: 22m 48s | F15: =A15 -> amelia.horwood@options-it.com
A16: sakib.malik@zomato.com | B16: 46162.282 | C16: 9044 | D16: 22 | E16: 22m 58s | F16: =A16 -> sakib.malik@zomato.com
A17: oli@gearset.com | B17: 46160.549 | C17: 8986 | D17: 23 | E17: 23m 04s | F17: =A17 -> oli@gearset.com
A18: raunak.shamnani@zomato.com | B18: 46164.545 | C18: 9107 | D18: 23 | E18: 23m 16s | F18: =A18 -> raunak.shamnani@zomato.com
A19: lakshminarayanan.sridhar@ig.com | B19: 46161.463 | C19: 9025 | D19: 24 | E19: 24m 16s | F19: =A19 -> lakshminarayanan.sridhar@ig.com
A20: roberta.roccia@thetrainline.com | B20: 46169.464 | C20: 9155 | D20: 24 | E20: 24m 40s | F20: =A20 -> roberta.roccia@thetrainline.com
A21: akshat.goel@zomato.com | B21: 46170.42 | C21: 9175 | D21: 24 | E21: 24m 54s | F21: =A21 -> akshat.goel@zomato.com
A22: hamish.dewar@exclaimer.com | B22: 46170.42 | C22: 9176 | D22: 25 | E22: 25m 24s | F22: =A22 -> hamish.dewar@exclaimer.com
A23: chris.davis@storiogroup.com | B23: 46160.424 | C23: 8974 | D23: 25 | E23: 25m 56s | F23: =A23 -> chris.davis@storiogroup.com
A24: jas.sahi@6dg.co.uk | B24: 46162.545 | C24: 9056 | D24: 26 | E24: 26m 07s | F24: =A24 -> jas.sahi@6dg.co.uk
A25: caoimhe.kelly@options-it.com | B25: 46162.426 | C25: 9050 | D25: 26 | E25: 26m 25s | F25: =A25 -> caoimhe.kelly@options-it.com
... A63: peter.graham@options-it.com | B63: 46157.422 | C63: 8936 | D63: 45 | E63: 45m 09s | F63: =A63 -> peter.graham@options-it.com
A64: a.strakovich@gmail.com | B64: 46164.463 | C64: 9101 | F64: =A64 -> a.strakovich@gmail.com

Sheet Sheet1
A1: player | B1: started | C1: session_id | D1: minutes | E1: duration | F1: player cc | G1: attempts | H1: attempt_number
A2: aamir.kapasi@albelli.com | B2: 46162.379 | C2: 9048 | F2: aamir.kapasi@albelli.com | G2: 1 | H2: 1
A3: a.strakovich@gmail.com | B3: 46164.463 | C3: 9101 | F3: a.strakovich@gmail.com | G3: 1 | H3: 1
A4: zishan.sohail@6dg.co.uk | B4: 46163.587 | C4: 9087 | F4: zishan.sohail@6dg.co.uk | G4: 1 | H4: 1
A5: william.vanduynhoven@thomsonreuters.com | B5: 46156.635 | C5: 8923 | F5: william.vanduynhoven@thomsonreuters.com | G5: 1 | H5: 1
A6: venkatmohan.kumar@ig.com | B6: 46163.425 | C6: 9077 | F6: venkatmohan.kumar@ig.com | G6: 1 | H6: 1
A7: umar.farooque@6dg.co.uk | B7: 46171.472 | C7: 9202 | F7: umar.farooque@6dg.co.uk | G7: 1 | H7: 1
A8: tim.redding@photobox.com | B8: 46162.549 | C8: 9059 | F8: tim.redding@photobox.com | G8: 1 | H8: 1
A9: swetha.nayudu@dominos.co.uk | B9: 46176.53 | C9: 9311 | F9: swetha.nayudu@dominos.co.uk | G9: 3 | H9: 2
A10: swetha.nayudu@dominos.co.uk | B10: 46162.549 | C10: 9058 | F10: swetha.nayudu@dominos.co.uk | G10: 3 | H10: 1
A11: shea_mcsorley@firstderivative.com | B11: 46176.466 | C11: 9305 | F11: shea_mcsorley@firstderivative.com | G11: 1 | H11: 1
A12: samantha.wright@exclaimer.com | B12: 46176.463 | C12: 9304 | F12: samantha.wright@exclaimer.com | G12: 1 | H12: 1
A13: remi.deverclos@albelli.com | B13: 46176.38 | C13: 9291 | F13: remi.deverclos@albelli.com | G13: 1 | H13: 1
... A27: naeem.khan@6dg.co.uk | B27: 46160.641 | C27: 8998 | F27: naeem.khan@6dg.co.uk | G27: 1 | H27: 1
A28: soumya.jk@thetrainline.com | B28: 46162.548 | C28: 9057 | D28: 20 | E28: 20m 14s | F28: soumya.jk@thetrainline.com | G28: 1 | H28: 1
A29: amy.jeanes@exclaimer.com | B29: 46170.545 | C29: 9185 | D29: 20 | E29: 20m 29s | F29: amy.jeanes@exclaimer.com | G29: 1 | H29: 1
A30: swetha.nayudu@dominos.co.uk | B30: 46176.567 | C30: 9317 | D30: 20 | E30: 20m 40s | F30: swetha.nayudu@dominos.co.uk | G30: 3 | H30: 3
A31: amelia.horwood@options-it.com | B31: 46170.385 | C31: 9173 | D31: 22 | E31: 22m 48s | F31: amelia.horwood@options-it.com | G31: 1 | H31: 1
A32: sakib.malik@zomato.com | B32: 46162.282 | C32: 9044 | D32: 22 | E32: 22m 58s | F32: sakib.malik@zomato.com | G32: 1 | H32: 1
A33: oli@gearset.com | B33: 46160.549 | C33: 8986 | D33: 23 | E33: 23m 04s | F33: oli@gearset.com | G33: 1 | H33: 1
A34: raunak.shamnani@zomato.com | B34: 46164.545 | C34: 9107 | D34: 23 | E34: 23m 16s | F34: raunak.shamnani@zomato.com | G34: 1 | H34: 1
A35: lana.m@slice.com | B35: 46175.631 | C35: 9280 | D35: 23 | E35: 23m 22s | F35: lana.m@slice.com | G35: 1 | H35: 1
A36: shea_hoey@firstderivative.com | B36: 46175.457 | C36: 9258 | D36: 23 | E36: 23m 30s | F36: shea_hoey@firstderivative.com | G36: 1 | H36: 1
A37: lakshminarayanan.sridhar@ig.com | B37: 46161.463 | C37: 9025 | D37: 24 | E37: 24m 16s | F37: lakshminarayanan.sridhar@ig.com | G37: 1 | H37: 1
A38: roberta.roccia@thetrainline.com | B38: 46169.464 | C38: 9155 | D38: 24 | E38: 24m 40s | F38: roberta.roccia@thetrainline.com | G38: 1 | H38: 1
A39: andrew.mccready@storiogroup.com | B39: 46175.506 | C39: 9267 | D39: 24 | E39: 24m 42s | F39: andrew.mccready@storiogroup.com | G39: 1 | H39: 1
... A108: arek.jadwiszczak@thomsonreuters.com | B108: 46169.549 | C108: 9162 | D108: 45 | E108: 45m 12s | F108: arek.jadwiszczak@thomsonreuters.com | G108: 1 | H108: 1
