Workbook

Sheet GUOT
A3: Row Labels | B3: Average of GUOT
A4: 45748 | B4: 8
A5: 45778 | B5: 9
A6: 45809 | B6: 9.7272727
A7: 45839 | B7: 9
A8: 45870 | B8: 9.1111111
A9: 45901 | B9: 9.25
A10: 45931 | B10: 8.9259259
A11: 45962 | B11: 8.8275862
A12: 45992 | B12: 9.1428571
A13: 46023 | B13: 9.05
A14: 46054 | B14: 8.6666667
A15: 46082 | B15: 9.1666667
A16: (blank)
A17: Grand Total | B17: 9.0178571

Sheet airtable
A1: Date | B1: month | C1: Time | D1: Name | E1: Company | F1: Sessions Done | G1: Session Plan | H1: AI | I1: Lead | J1: Star Guru | K1: Session Notes | L1: GUOT | M1: Score Notes | N1: Session ID | O1: Feedback Quality Score | P1: Feedback Notes | Q1: Attendance | R1: Attendance Reason | S1: INC # | T1: Technical Issues | U1: Technical Issue Reason | V1: Notes for Mildred
A2: 45776 | B2: =DATE(YEAR(A2), MONTH(A2), 1) -> 45748 | C2: 0.45833333 | D2: Jamie | E2: Options IT | F2: 17 | G2: Intro | I2: Karan | J2: Naz | L2: No Score | M2: Jamie is Operations team Engineer for Change Release - He has more than 15 years of experience in Option-IT right from first line support engineer to Change manager . He covers change mgmt, CAB calls, Operation calls and customer communication during Major Incidents . UK and US time has better incident management coverage compared to APAC due to less experienced and junior staff in APAC | Q2: Attended
A3: 45777 | B3: =DATE(YEAR(A3), MONTH(A3), 1) -> 45748 | C3: 0.41666667 | D3: Jack | E3: Options IT | F3: 17 | G3: Onboarding,Too Good To Be True | I3: Joe | J3: Karan | L3: 8 | M3: He scored 8 since he thought its his performance and since LO was guiding him - he felt he could've done much better . He liked the simulation platform and getting used to Slack . For Drill he owuld definitly score 10 | N3: 4049 | Q3: Attended
A4: 45777 | B4: =DATE(YEAR(A4), MONTH(A4), 1) -> 45748 | C4: 0.625 | D4: Ritchie | E4: Options IT | F4: 13 | I4: Naz | J4: Rishi | Q4: No Show | R4: He was caught up in a meeting
A5: 45778 | B5: =DATE(YEAR(A5), MONTH(A5), 1) -> 45778 | C5: 0.64583333 | D5: Ciara | E5: Options IT | F5: 16 | G5: Onboarding,Too Good To Be True | I5: Naz | J5: Rishi | L5: 9 | M5: She is a young Technical Support Engineer, handling security and various issues. She found our platform similar to real-life scenarios and liked it, although she may need a bit more time to get used to it. Her confidence level is around 6–7. She has 1.5 years of experience, all within Options IT. | N5: 4085 | Q5: Attended
A6: 45779 | B6: =DATE(YEAR(A6), MONTH(A6), 1) -> 45778 | C6: 0.625 | D6: Jamie | E6: Options IT | F6: 17 | Q6: Cancelled | R6: He has a call during this time
A7: 45784 | B7: =DATE(YEAR(A7), MONTH(A7), 1) -> 45778 | C7: 0.41666667 | D7: Jack | E7: Options IT | F7: 17 | G7: Bez Beatles Day | I7: Karan | J7: Rishi | L7: 10 | M7: Surprise : Senior engineer pushing back can happen in real life | N7: 4131 | Q7: Attended
A8: 45784 | B8: =DATE(YEAR(A8), MONTH(A8), 1) -> 45778 | C8: 0.625 | D8: Ritchie | E8: Options IT | F8: 13 | G8: Intro | I8: Karan | L8: No Score | M8: Ritchie is in IT Options from 7 montsh and has overall 5 year sof experience . His role is Tech support engineer and they are client facing , gets information from clients and feed it to tech team - Biggest challenge during P1 is to get the engineers responsible to bring on cal to resolve incident | Q8: Attended
A9: 45785 | B9: =DATE(YEAR(A9), MONTH(A9), 1) -> 45778 | C9: 0.64583333 | D9: Ciara | E9: Options IT | F9: 16 | G9: Bez Beatles Day | I9: Rishi | J9: Clara | L9: 9 | M9: Good close to reality , bit more difficult than last time. What did the player like or find surprising? The way Dan was adamant over his change. Why did she gave this score ? Nothing major comments when asked. Getting along with the platform. | N9: 4150 | Q9: Attended
A10: 45789 | B10: =DATE(YEAR(A10), MONTH(A10), 1) -> 45778 | C10: 0.54166667 | D10: Jamie | E10: Options IT | F10: 17 | G10: Too Good To Be True | I10: Karan | J10: Rishi | L10: 8 | M10: Human responses are realistic - Impressed with great responses from BOTS - Surprise : How speedy the BOTS responded and it was human like . Why 8 ??: Options we use different tool set which are different than what we use in Online Boutique - If they can integrate the tools they use in Options IT in OB - That would be great | N10: 4172 | Q10: Attended
A11: 45791 | B11: =DATE(YEAR(A11), MONTH(A11), 1) -> 45778 | C11: 0.41666667 | D11: Jack | E11: Options IT | F11: 17 | Q11: Internal Reschedule/Cancellation | R11: Due to conference
A12: 45791 | B12: =DATE(YEAR(A12), MONTH(A12), 1) -> 45778 | C12: 0.625 | D12: Ritchie | E12: Options IT | F12: 13 | Q12: Internal Reschedule/Cancellation | R12: Due to conference
A13: 45792 | B13: =DATE(YEAR(A13), MONTH(A13), 1) -> 45778 | C13: 0.64583333 | D13: Ciara | E13: Options IT | F13: 16 | Q13: Internal Reschedule/Cancellation | R13: Due to conference
A14: 45793 | B14: =DATE(YEAR(A14), MONTH(A14), 1) -> 45778 | C14: 0.64583333 | D14: Zach | E14: Options IT | F14: 8 | G14: Intro,Onboarding,Too Good To Be True | I14: Naz | J14: Conail | L14: 10 | M14: He likes the platform. He is going to use the platform and looking forward to play more drills | N14: 4271 | Q14: Attended
A15: 45796 | B15: =DATE(YEAR(A15), MONTH(A15), 1) -> 45778 | C15: 0.54166667 | D15: Jamie | E15: Options IT | F15: 17 | G15: Bez Beatles Day | I15: Karan | J15: Rishi | L15: 8 | M15: It was stress-ful - a lot to think about - Like the human element of it due to resistance to roll back . Why 8 : He might not be absolute demography for this since he is seasoned Incident manager - He would give 10 if he learn something new - In this specific incident he didn't learn anything new | N15: 4275 | Q15: Attended
A16: 45798 | B16: =DATE(YEAR(A16), MONTH(A16), 1) -> 45778 | C16: 0.41666667 | D16: Jack | E16: Options IT | F16: 17 | Q16: Cancelled | R16: He is OOO
A17: 45798 | B17: =DATE(YEAR(A17), MONTH(A17), 1) -> 45778 | C17: 0.625 | D17: Ritchie | E17: Options IT | F17: 13 | G17: Onboarding,Too Good To Be True | I17: Karan | J17: Naz | L17: 9 | M17: Much better than what i was expecting - Surprised with the fact that the character responses are so relevant . What can we do to make it 10 : Slight confusion of being overwhelmed with too many tasks - this might change once i get familiar with platform | N17: 4315 | Q17: Attended
A18: 45799 | B18: =DATE(YEAR(A18), MONTH(A18), 1) -> 45778 | C18: 0.64583333 | D18: Ciara | E18: Options IT | F18: 16 | G18: The Big Investors | I18: Rishi | J18: Charlene | L18: 10 | M18: Enjoying it, and good to experience how it's getting more challenging every week. She finds it realistic and the drill's resemblance to real-life at work as well. | N18: 4332 | Q18: Attended
A19: 45800 | B19: =DATE(YEAR(A19), MONTH(A19), 1) -> 45778 | C19: 0.64583333 | D19: Zach | E19: Options IT | F19: 8 | Q19: Cancelled | R19: He is OOO
A20: 45805 | B20: =DATE(YEAR(A20), MONTH(A20), 1) -> 45778 | C20: 0.41666667 | D20: Jack | E20: Options IT | F20: 17 | G20: The Big Investors | I20: Karan | J20: Ed | L20: 9 | M20: What could make it 10 ? I think, it was probably a 10 - i put 9 because that he should have picked it up well but he should have used team to do the job | N20: 4370 | Q20: Attended
A21: 45805 | B21: =DATE(YEAR(A21), MONTH(A21), 1) -> 45778 | C21: 0.625 | D21: Ritchie | E21: Options IT | F21: 13 | I21: Rishi | J21: Karan | Q21: Late Cancellation | R21: Rishi and Karan were already in the call
A22: 45806 | B22: =DATE(YEAR(A22), MONTH(A22), 1) -> 45778 | C22: 0.64583333 | D22: Ciara | E22: Options IT | F22: 16 | G22: Rumours | I22: Rishi | J22: Ed | L22: 8 | M22: Liking the overall setup of tools and dashboards. Why 8? She was rating the drill as it was just for a single user. Earlier ones were impacting regions or the global scale. | N22: 4391 | Q22: Attended
A23: 45807 | B23: =DATE(YEAR(A23), MONTH(A23), 1) -> 45778 | C23: 0.64583333 | D23: Zach | E23: Options IT | F23: 8 | I23: Ed | J23: Rishi | Q23: Late Cancellation | R23: can't join
A24: 45810 | B24: =DATE(YEAR(A24), MONTH(A24), 1) -> 45809 | C24: 0.54166667 | D24: Jamie | E24: Options IT | F24: 17 | Q24: Early Cancellation | R24: He is OOO
A25: 45812 | B25: =DATE(YEAR(A25), MONTH(A25), 1) -> 45809 | C25: 0.41666667 | D25: Jack | E25: Options IT | F25: 17 | Q25: Cancelled | R25: There's a live issue
A26: 45812 | B26: =DATE(YEAR(A26), MONTH(A26), 1) -> 45809 | C26: 0.625 | D26: Ritchie | E26: Options IT | F26: 13 | G26: Bez Beatles Day | I26: Karan | J26: Charlene | L26: 9 | M26: Interesting how some engineers can push back - Felt realistic . Surprise : I thought tough to tell senior engineer to tell to look back at their work . Why 9 ? Nothing comes to my mind - I could give a 10 | N26: 4474 | Q26: Attended | S26: INC-229 Drill Kubernetes Dashboard not registering in teleport | T26: checked | U26: The k8s dashboard doesn't show up in teleport. We need to add states
A27: 45813 | B27: =DATE(YEAR(A27), MONTH(A27), 1) -> 45809 | C27: 0.64583333 | D27: Ciara | E27: Options IT | F27: 16 | Q27: Rescheduled | R27: Asked to reschedule the following day
A28: 45814 | B28: =DATE(YEAR(A28), MONTH(A28), 1) -> 45809 | C28: 0.5 | D28: Ciara | E28: Options IT | F28: 16 | G28: Radio Silence | I28: Rishi | J28: Drew | L28: 10 | M28: She observed Tanya's unresponsiveness. Liked the different scenario as it brings different experience every time | N28: 4500 | Q28: Attended
A29: 45814 | B29: =DATE(YEAR(A29), MONTH(A29), 1) -> 45809 | C29: 0.64583333 | D29: Zach | E29: Options IT | F29: 8 | G29: Bez Beatles Day | I29: Ed | J29: Karan | L29: 10 | M29: He thinks drill do very well as for what they are designed for. He is looking forward to his next session | N29: 4504 | Q29: Attended
A30: 45817 | B30: =DATE(YEAR(A30), MONTH(A30), 1) -> 45809 | C30: 0.54166667 | D30: Jamie | E30: Options IT | F30: 17 | G30: The Big Investors | I30: Rishi | J30: Leon | L30: 10 | M30: its good. He liked the push of not getting something easily as it was not caused due to a change. And he wants to play more sort of these drills where change is not a culprit. | N30: 4514 | Q30: Attended
A31: 45819 | B31: =DATE(YEAR(A31), MONTH(A31), 1) -> 45809 | C31: 0.41666667 | D31: Jack | E31: Options IT | F31: 17 | G31: Rumours | I31: Ed | J31: Joe | L31: 10 | M31: He needs to focus on impact assessment (nail that over the next 1 or 2 drills) - didn't spot the local issue quickly in Rumours Enjoyed the session, find it useful to practice drills once a week especially since they are booked into the calendar My notes (Joe) * happy to play week, but i recomemended after baout 6, we will reduce the cadence to fortnighlty * he did ask about a profile session (i suggest he gets in the next 1 or 2 sesssion) | N31: 4540 | Q31: Attended
A32: 45819 | B32: =DATE(YEAR(A32), MONTH(A32), 1) -> 45809 | C32: 0.625 | D32: Ritchie | E32: Options IT | F32: 13 | G32: The Big Investors | I32: Rishi | J32: Drew | L32: 8 | M32: Why 8 ? He liked the experience but mentioned it to be very similar to the previous one - same error and same issues (Daniel) , that's why less challenging than earlier one. | N32: 4548 | Q32: Attended | T32: checked | U32: When op console froze for about 40 seconds during a CS session, character messages or stars weren't getting sent on time due to it
A33: 45820 | B33: =DATE(YEAR(A33), MONTH(A33), 1) -> 45809 | C33: 0.64583333 | D33: Ciara | E33: Options IT | F33: 16 | K33: Next session: Missing Delivery | Q33: Rescheduled | R33: Did not provide any reason
A34: 45821 | B34: =DATE(YEAR(A34), MONTH(A34), 1) -> 45809 | C34: 0.5 | D34: Ciara | E34: Options IT | F34: 16 | G34: Missing Delivery | I34: Charlene | J34: Juan | L34: 10 | M34: She enjoyed the session liked that it was different from other drills she's played as it wasn't changed related. Her confidence seems to have risen as she's engaging with the characters really well, just mentioned she needs to focus now on the business comms. | N34: 4586 | Q34: Attended
A35: 45821 | B35: =DATE(YEAR(A35), MONTH(A35), 1) -> 45809 | C35: 0.64583333 | D35: Zach | E35: Options IT | F35: 8 | Q35: Cancelled
A36: 45824 | B36: =DATE(YEAR(A36), MONTH(A36), 1) -> 45809 | C36: 0.54166667 | D36: Jamie | E36: Options IT | F36: 17 | Q36: Cancelled | R36: Something has come up and won't be able to join the session today.
A37: 45826 | B37: =DATE(YEAR(A37), MONTH(A37), 1) -> 45809 | C37: 0.41666667 | D37: Jack | E37: Options IT | F37: 17 | G37: Missing Delivery | I37: Ed | J37: Karan | K37: Added some notes for his next session | L37: 10 | M37: He liked the drill, and he is looking forward to trying Missing delivery +. Also, he is keen to know where he sits within the team/company feedback on Jack that we can note for the coaching Peter recommended that we help Jack with practicing facts over opinion (validating advice, feedback from the investigating Devs) | N37: 4624 | Q37: Attended
A38: 45826 | B38: =DATE(YEAR(A38), MONTH(A38), 1) -> 45809 | C38: 0.625 | D38: Ritchie | E38: Options IT | F38: 13 | Q38: Cancelled | R38: Did not provide any reason
A39: 45826 | B39: =DATE(YEAR(A39), MONTH(A39), 1) -> 45809 | C39: 0.66666667 | D39: Account Meeting | E39: Options IT | G39: Account Meeting
A40: 45827 | B40: =DATE(YEAR(A40), MONTH(A40), 1) -> 45809 | C40: 0.64583333 | D40: Ciara | E40: Options IT | F40: 16 | Q40: Cancelled
...

Sheet cohort
A1: player | B1: cohort
A2: amelia.horwood | B2: 3
A3: aoife.breen | B3: 2
A4: caoimhe.kelly | B4: x
A5: ciara.scullion | B5: 1
A6: donnchadh.tierney | B6: 3
A7: ellie.walsh | B7: 2
A8: elsa.savage | B8: 2
A9: emma.allsopp | B9: 2
A10: jack.walsh | B10: 1
A11: james.sheppy | B11: 3
A12: jamie.dow | B12: 1
A13: jessica.mcdonald | B13: 4
A14: leah.murphy | B14: 3
A15: mark.mcgarry | B15: 3
A16: patrick.collins | B16: 4
A17: peter.graham | B17: x
A18: ritchie.mcgrath | B18: 1
A19: sinead.glennon | B19: 2
A20: storm.chambers | B20: 2
A21: zach.davis | B21: 1

Sheet pivot
A1: month | B1: (All)
A3: Row Labels | B3: Count of session_start
A4: 1 | B4: 58
A5: ciara.scullion | B5: 13
A6: jack.walsh | B6: 14
A7: jamie.dow | B7: 13
A8: ritchie.mcgrath | B8: 10
A9: zach.davis | B9: 8
A10: 2 | B10: 47
A11: aoife.breen | B11: 11
A12: ellie.walsh | B12: 9
A13: elsa.savage | B13: 9
A14: emma.allsopp | B14: 10
A15: sinead.glennon | B15: 1
A16: storm.chambers | B16: 7
A17: 3 | B17: 36
A18: amelia.horwood | B18: 7
A19: donnchadh.tierney | B19: 6
A20: james.sheppy | B20: 7
A21: leah.murphy | B21: 8
A22: mark.mcgarry | B22: 8
A23: 4 | B23: 6
A24: jessica.mcdonald | B24: 5
A25: patrick.collins | B25: 1
A26: Grand Total | B26: 147
A30: month | B30: (All)
A32: Row Labels | B32: Incident Mechanics | C32: Commanding The Incident | D32: Internal Comms | E32: External Comms | F32: Identify Scope | G32: Session Count
A33: amelia.horwood | B33: 0.78571429 | C33: 0.15584416 | D33: 0.37142857 | E33: 0.61904762 | F33: 0.58730159 | G33: 7
A34: aoife.breen | B34: 1 | C34: 0.38842975 | D34: 0.52121212 | E34: 0.54545455 | F34: 0.75757576 | G34: 11
A35: caoimhe.kelly | B35: 0.875 | C35: 0.23863636 | D35: 0.45 | E35: 0.54166667 | F35: 0.54166667 | G35: 8
A36: ciara.scullion | B36: 0.84615385 | C36: 0.34965035 | D36: 0.48717949 | E36: 0.57692308 | F36: 0.53846154 | G36: 13
A37: donnchadh.tierney | B37: 0.83333333 | C37: 0.22727273 | D37: 0.4 | E37: 0.63888889 | F37: 0.57407407 | G37: 6
A38: ellie.walsh | B38: 0.72222222 | C38: 0.22222222 | D38: 0.39259259 | E38: 0.51851852 | F38: 0.59259259 | G38: 9
A39: elsa.savage | B39: 0.72222222 | C39: 0.25252525 | D39: 0.41481481 | E39: 0.59259259 | F39: 0.61728395 | G39: 9
A40: emma.allsopp | B40: 1 | C40: 0.31818182 | D40: 0.44 | E40: 0.63333333 | F40: 0.57777778 | G40: 10
A41: jack.walsh | B41: 0.85714286 | C41: 0.42207792 | D41: 0.59047619 | E41: 0.57142857 | F41: 0.68253968 | G41: 14
A42: james.sheppy | B42: 0.57142857 | C42: 0.19480519 | D42: 0.38095238 | E42: 0.52380952 | F42: 0.55555556 | G42: 7
A43: jamie.dow | B43: 0.96153846 | C43: 0.43356643 | D43: 0.62564103 | E43: 0.61538462 | F43: 0.72649573 | G43: 13
A44: jessica.mcdonald | B44: 0.6 | C44: 0.23636364 | D44: 0.44 | E44: 0.33333333 | F44: 0.57777778 | G44: 5
... A52: zach.davis | B52: 0.9375 | C52: 0.20454545 | D52: 0.375 | E52: 0.58333333 | F52: 0.45833333 | G52: 8
...

Sheet Graphs

Sheet optionsdata_for_dashboard
A1: session_start | B1: month | C1: day_of_week | D1: duration | E1: level | F1: name | G1: player | H1: cohort | I1: completion_status | J1: identify_scope | K1: incident_mechanics | L1: external_comms | M1: internal_comms | N1: commanding_the_incident | O1: Complexity: Ambiguous cues (multiple alternatives) | P1: Complexity: Attention Demands | Q1: Complexity: Conflicting Advice | R1: Complexity: Decreased access to team members | S1: Complexity: Distributed information across individuals/organiza | T1: Complexity: Doublebind situations (dilemmas) | U1: Complexity: False prime explanations (garden path) | V1: Complexity: Hidden coupling (effects at a distance; cascading e | W1: Complexity: Implied relationship (red herring) | X1: Complexity: Interdependencies amongst roles (someone needs some | Y1: Complexity: Lack of predefined plan | Z1: Complexity: Misleading indicators (low predictive value) | AA1: Complexity: Mismatch between prede fined plans or procedures an | AB1: Complexity: Missing Information | AC1: Complexity: Multi Party Dilema | AD1: Complexity: Multiple simultaneous influences (more than one exp | AE1: Complexity: Multiple simultaneous influences (multiple explanat | AF1: Complexity: Saturation | AG1: Complexity: Simultaneous seperate issues | AH1: Complexity: Stakeholder Interference | AI1: Complexity: Stereotype violations (not the usual suspect) | AJ1: Complexity: Stress or fatigue | AK1: Complexity: Uncertain information (unreliable data) | AL1: Complexity: Unintended effects (managing side effects) | AM1: Complexity: Absence of strong signals (no alarms, no threshold | AN1: max | AO1: Category: Detecting | AP1: Category: Sensemaking | AQ1: Category: Planning | AR1: Category: Deciding | AS1: Category: Coordination | AT1: Category: Executing
A2: 2025-04-30 01:00:00.000 +0100 | B2: =DATE(YEAR(DATEVALUE(LEFT(A2,10))), MONTH(DATEVALUE(LEFT(A2,10))), 1) -> 45748 | C2: Wednesday | D2: 0.009525463 | E2: 3 | F2: Too Good To Be True | G2: jack.walsh | H2: =VLOOKUP(G2, cohort!A$2:B$21, 2, FALSE) -> 1 | I2: COMPLETED | J2: 0.77777778 | K2: 1 | L2: 0.66666667 | M2: 0.6 | N2: 0.27272727 | O2: 0 | P2: 0 | Q2: 1 | R2: 0 | S2: 0 | T2: 0 | U2: 0 | V2: 0 | W2: 0 | X2: 0 | Y2: 0 | Z2: 0 | AA2: 0 | AB2: 0 | AC2: 0 | AD2: 0 | AE2: 0 | AF2: 0 | AG2: 0 | AH2: 0 | AI2: 0 | AJ2: 0 | AK2: 1 | AL2: 0 | AM2: 0 | AN2: - | AO2: 0 | AP2: 1 | AQ2: 2 | AR2: 0 | AS2: 0 | AT2: 0
A3: 2025-04-30 01:00:00.000 +0100 | B3: =DATE(YEAR(DATEVALUE(LEFT(A3,10))), MONTH(DATEVALUE(LEFT(A3,10))), 1) -> 45748 | C3: Wednesday | D3: 0.013900463 | E3: 3 | F3: Too Good To Be True | G3: jack.walsh | H3: =VLOOKUP(G3, cohort!A$2:B$21, 2, FALSE) -> 1 | I3: OUT_OF_TIME | J3: 0 | K3: 0.5 | L3: 0.33333333 | M3: 0 | N3: 0 | O3: 0 | P3: 0 | Q3: 1 | R3: 0 | S3: 0 | T3: 0 | U3: 0 | V3: 0 | W3: 0 | X3: 0 | Y3: 0 | Z3: 0 | AA3: 0 | AB3: 0 | AC3: 0 | AD3: 0 | AE3: 0 | AF3: 0 | AG3: 0 | AH3: 0 | AI3: 0 | AJ3: 0 | AK3: 1 | AL3: 0 | AM3: 0 | AN3: - | AO3: 0 | AP3: 1 | AQ3: 2 | AR3: 0 | AS3: 0 | AT3: 0
A4: 2025-05-01 01:00:00.000 +0100 | B4: =DATE(YEAR(DATEVALUE(LEFT(A4,10))), MONTH(DATEVALUE(LEFT(A4,10))), 1) -> 45778 | C4: Thursday | D4: 0.013900463 | E4: 3 | F4: Too Good To Be True | G4: ciara.scullion | H4: =VLOOKUP(G4, cohort!A$2:B$21, 2, FALSE) -> 1 | I4: OUT_OF_TIME | J4: 0.33333333 | K4: 1 | L4: 0.5 | M4: 0.46666667 | N4: 0.18181818 | O4: 0 | P4: 0 | Q4: 1 | R4: 0 | S4: 0 | T4: 0 | U4: 0 | V4: 0 | W4: 0 | X4: 0 | Y4: 0 | Z4: 0 | AA4: 0 | AB4: 0 | AC4: 0 | AD4: 0 | AE4: 0 | AF4: 0 | AG4: 0 | AH4: 0 | AI4: 0 | AJ4: 0 | AK4: 1 | AL4: 0 | AM4: 0 | AN4: - | AO4: 0 | AP4: 1 | AQ4: 2 | AR4: 0 | AS4: 0 | AT4: 0
A5: 2025-05-07 01:00:00.000 +0100 | B5: =DATE(YEAR(DATEVALUE(LEFT(A5,10))), MONTH(DATEVALUE(LEFT(A5,10))), 1) -> 45778 | C5: Wednesday | D5: 0.0094444444 | E5: 5 | F5: Bezs Beatles Day! | G5: jack.walsh | H5: =VLOOKUP(G5, cohort!A$2:B$21, 2, FALSE) -> 1 | I5: COMPLETED | J5: 0.77777778 | K5: 1 | L5: 0.66666667 | M5: 0.6 | N5: 0.36363636 | O5: 0 | P5: 0 | Q5: 1 | R5: 0 | S5: 0 | T5: 0 | U5: 0 | V5: 0 | W5: 0 | X5: 0 | Y5: 0 | Z5: 1 | AA5: 0 | AB5: 0 | AC5: 0 | AD5: 0 | AE5: 0 | AF5: 0 | AG5: 0 | AH5: 0 | AI5: 0 | AJ5: 0 | AK5: 0 | AL5: 0 | AM5: 0 | AN5: - | AO5: 0 | AP5: 1 | AQ5: 1 | AR5: 0 | AS5: 0 | AT5: 0
A6: 2025-05-08 01:00:00.000 +0100 | B6: =DATE(YEAR(DATEVALUE(LEFT(A6,10))), MONTH(DATEVALUE(LEFT(A6,10))), 1) -> 45778 | C6: Thursday | D6: 0.014050926 | E6: 5 | F6: Bezs Beatles Day! | G6: ciara.scullion | H6: =VLOOKUP(G6, cohort!A$2:B$21, 2, FALSE) -> 1 | I6: COMPLETED | J6: 0.66666667 | K6: 0 | L6: 0.16666667 | M6: 0.46666667 | N6: 0.27272727 | O6: 0 | P6: 0 | Q6: 1 | R6: 0 | S6: 0 | T6: 0 | U6: 0 | V6: 0 | W6: 0 | X6: 0 | Y6: 0 | Z6: 1 | AA6: 0 | AB6: 0 | AC6: 0 | AD6: 0 | AE6: 0 | AF6: 0 | AG6: 0 | AH6: 0 | AI6: 0 | AJ6: 0 | AK6: 0 | AL6: 0 | AM6: 0 | AN6: - | AO6: 0 | AP6: 1 | AQ6: 1 | AR6: 0 | AS6: 0 | AT6: 0
A7: 2025-05-12 01:00:00.000 +0100 | B7: =DATE(YEAR(DATEVALUE(LEFT(A7,10))), MONTH(DATEVALUE(LEFT(A7,10))), 1) -> 45778 | C7: Monday | D7: 0.010902778 | E7: 3 | F7: Too Good To Be True | G7: jamie.dow | H7: =VLOOKUP(G7, cohort!A$2:B$21, 2, FALSE) -> 1 | I7: COMPLETED | J7: 0.55555556 | K7: 1 | L7: 0.66666667 | M7: 0.53333333 | N7: 0.18181818 | O7: 0 | P7: 0 | Q7: 1 | R7: 0 | S7: 0 | T7: 0 | U7: 0 | V7: 0 | W7: 0 | X7: 0 | Y7: 0 | Z7: 0 | AA7: 0 | AB7: 0 | AC7: 0 | AD7: 0 | AE7: 0 | AF7: 0 | AG7: 0 | AH7: 0 | AI7: 0 | AJ7: 0 | AK7: 1 | AL7: 0 | AM7: 0 | AN7: - | AO7: 0 | AP7: 1 | AQ7: 2 | AR7: 0 | AS7: 0 | AT7: 0
A8: 2025-05-16 01:00:00.000 +0100 | B8: =DATE(YEAR(DATEVALUE(LEFT(A8,10))), MONTH(DATEVALUE(LEFT(A8,10))), 1) -> 45778 | C8: Friday | D8: 0.0099884259 | E8: 3 | F8: Too Good To Be True | G8: zach.davis | H8: =VLOOKUP(G8, cohort!A$2:B$21, 2, FALSE) -> 1 | I8: COMPLETED | J8: 0 | K8: 0.5 | L8: 0.5 | M8: 0.13333333 | N8: 0 | O8: 0 | P8: 0 | Q8: 1 | R8: 0 | S8: 0 | T8: 0 | U8: 0 | V8: 0 | W8: 0 | X8: 0 | Y8: 0 | Z8: 0 | AA8: 0 | AB8: 0 | AC8: 0 | AD8: 0 | AE8: 0 | AF8: 0 | AG8: 0 | AH8: 0 | AI8: 0 | AJ8: 0 | AK8: 1 | AL8: 0 | AM8: 0 | AN8: - | AO8: 0 | AP8: 1 | AQ8: 2 | AR8: 0 | AS8: 0 | AT8: 0
A9: 2025-05-19 01:00:00.000 +0100 | B9: =DATE(YEAR(DATEVALUE(LEFT(A9,10))), MONTH(DATEVALUE(LEFT(A9,10))), 1) -> 45778 | C9: Monday | D9: 0.012384259 | E9: 5 | F9: Bezs Beatles Day! | G9: jamie.dow | H9: =VLOOKUP(G9, cohort!A$2:B$21, 2, FALSE) -> 1 | I9: COMPLETED | J9: 1 | K9: 1 | L9: 0.5 | M9: 0.6 | N9: 0.36363636 | O9: 0 | P9: 0 | Q9: 1 | R9: 0 | S9: 0 | T9: 0 | U9: 0 | V9: 0 | W9: 0 | X9: 0 | Y9: 0 | Z9: 1 | AA9: 0 | AB9: 0 | AC9: 0 | AD9: 0 | AE9: 0 | AF9: 0 | AG9: 0 | AH9: 0 | AI9: 0 | AJ9: 0 | AK9: 0 | AL9: 0 | AM9: 0 | AN9: - | AO9: 0 | AP9: 1 | AQ9: 1 | AR9: 0 | AS9: 0 | AT9: 0
A10: 2025-05-21 01:00:00.000 +0100 | B10: =DATE(YEAR(DATEVALUE(LEFT(A10,10))), MONTH(DATEVALUE(LEFT(A10,10))), 1) -> 45778 | C10: Wednesday | D10: 0.0090625 | E10: 3 | F10: Too Good To Be True | G10: ritchie.mcgrath | H10: =VLOOKUP(G10, cohort!A$2:B$21, 2, FALSE) -> 1 | I10: COMPLETED | J10: 0.55555556 | K10: 1 | L10: 0.83333333 | M10: 0.4 | N10: 0.27272727 | O10: 0 | P10: 0 | Q10: 1 | R10: 0 | S10: 0 | T10: 0 | U10: 0 | V10: 0 | W10: 0 | X10: 0 | Y10: 0 | Z10: 0 | AA10: 0 | AB10: 0 | AC10: 0 | AD10: 0 | AE10: 0 | AF10: 0 | AG10: 0 | AH10: 0 | AI10: 0 | AJ10: 0 | AK10: 1 | AL10: 0 | AM10: 0 | AN10: - | AO10: 0 | AP10: 1 | AQ10: 2 | AR10: 0 | AS10: 0 | AT10: 0
A11: 2025-05-22 01:00:00.000 +0100 | B11: =DATE(YEAR(DATEVALUE(LEFT(A11,10))), MONTH(DATEVALUE(LEFT(A11,10))), 1) -> 45778 | C11: Thursday | D11: 0.013900463 | E11: 6 | F11: The Big Investor | G11: ciara.scullion | H11: =VLOOKUP(G11, cohort!A$2:B$21, 2, FALSE) -> 1 | I11: OUT_OF_TIME | J11: 0.44444444 | K11: 1 | L11: 0.33333333 | M11: 0.26666667 | N11: 0.27272727 | O11: 0 | P11: 0 | Q11: 0 | R11: 0 | S11: 0 | T11: 0 | U11: 0 | V11: 0 | W11: 1 | X11: 0 | Y11: 0 | Z11: 0 | AA11: 0 | AB11: 0 | AC11: 0 | AD11: 0 | AE11: 0 | AF11: 0 | AG11: 0 | AH11: 1 | AI11: 1 | AJ11: 1 | AK11: 0 | AL11: 0 | AM11: 0 | AN11: - | AO11: 0 | AP11: 2 | AQ11: 0 | AR11: 2 | AS11: 0 | AT11: 0
A12: 2025-05-28 01:00:00.000 +0100 | B12: =DATE(YEAR(DATEVALUE(LEFT(A12,10))), MONTH(DATEVALUE(LEFT(A12,10))), 1) -> 45778 | C12: Wednesday | D12: 0.012673611 | E12: 6 | F12: The Big Investor | G12: jack.walsh | H12: =VLOOKUP(G12, cohort!A$2:B$21, 2, FALSE) -> 1 | I12: COMPLETED | J12: 1 | K12: 1 | L12: 0.83333333 | M12: 0.66666667 | N12: 0.45454545 | O12: 0 | P12: 0 | Q12: 0 | R12: 0 | S12: 0 | T12: 0 | U12: 0 | V12: 0 | W12: 1 | X12: 0 | Y12: 0 | Z12: 0 | AA12: 0 | AB12: 0 | AC12: 0 | AD12: 0 | AE12: 0 | AF12: 0 | AG12: 0 | AH12: 1 | AI12: 1 | AJ12: 1 | AK12: 0 | AL12: 0 | AM12: 0 | AN12: - | AO12: 0 | AP12: 2 | AQ12: 0 | AR12: 2 | AS12: 0 | AT12: 0
A13: 2025-05-29 01:00:00.000 +0100 | B13: =DATE(YEAR(DATEVALUE(LEFT(A13,10))), MONTH(DATEVALUE(LEFT(A13,10))), 1) -> 45778 | C13: Thursday | D13: 0.012291667 | E13: 7 | F13: Rumours | G13: ciara.scullion | H13: =VLOOKUP(G13, cohort!A$2:B$21, 2, FALSE) -> 1 | I13: COMPLETED | J13: 0.55555556 | K13: 1 | L13: 0.66666667 | M13: 0.46666667 | N13: 0.45454545 | O13: 0 | P13: 0 | Q13: 0 | R13: 0 | S13: 0 | T13: 0 | U13: 1 | V13: 0 | W13: 1 | X13: 0 | Y13: 0 | Z13: 0 | AA13: 0 | AB13: 0 | AC13: 0 | AD13: 0 | AE13: 0 | AF13: 0 | AG13: 0 | AH13: 0 | AI13: 0 | AJ13: 1 | AK13: 0 | AL13: 0 | AM13: 0 | AN13: - | AO13: 0 | AP13: 2 | AQ13: 0 | AR13: 1 | AS13: 0 | AT13: 0
... A160: 2026-03-16 00:00:00.000 +0000 | B160: =DATE(YEAR(DATEVALUE(LEFT(A160,10))), MONTH(DATEVALUE(LEFT(A160,10))), 1) -> 46082 | C160: Monday | D160: 0.010925926 | E160: 16 | F160: Radio Silence | G160: jessica.mcdonald | H160: =VLOOKUP(G160, cohort!A$2:B$21, 2, FALSE) -> 4 | I160: COMPLETED | J160: 0.66666667 | K160: 0 | L160: 0.33333333 | M160: 0.4 | N160: 0.090909091 | O160: 0 | P160: 0 | Q160: 0 | R160: 1 | S160: 0 | T160: 0 | U160: 0 | V160: 0 | W160: 0 | X160: 0 | Y160: 0 | Z160: 0 | AA160: 0 | AB160: 1 | AC160: 0 | AD160: 0 | AE160: 0 | AF160: 0 | AG160: 0 | AH160: 0 | AI160: 0 | AJ160: 0 | AK160: 0 | AL160: 0 | AM160: 0 | AN160: - | AO160: 0 | AP160: 1 | AQ160: 0 | AR160: 0 | AS160: 1 | AT160: 0
